Workbook

Sheet README
A1: APARTSALES — FINANCIAL MODEL v1
A3: Версия | B3: v1.0 (29 апреля 2026)
A4: Авторы | B4: Billions X × Claude
A5: Связанный документ | B5: docs/APARTSALES-MODEL-v2.0.md
A6: Базовый сценарий | B6: Year 1 — Крым (Ялта/Алушта/Евпатория/Симферополь/Севастополь)
A8: СТРУКТУРА ФАЙЛА
A9: README | B9: Этот лист — навигация и легенда
A10: Inputs | B10: Все ассумпции в одном месте, 3 сценария в столбцах. Меняй здесь — пересчитывается всё
A11: Headcount | B11: План найма: роли × месяцы, РФ-ставки 2026, +30% страховых
A12: Revenue | B12: Помесячный build выручки через воронку (visitors → close)
A13: P&L Year 1 | B13: Помесячный P&L Year 1 для всех 3 сценариев параллельно
A14: 3-Year View | B14: Year 1 / Year 2 / Year 3 summary с расширением hubs
A15: Cap Table | B15: Структура раунда и use of funds
A17: ЛЕГЕНДА ЦВЕТОВ
A18: Синий текст | B18: Hardcoded input — меняй для сценариев
A19: Чёрный текст | B19: Формула / расчёт
A20: Зелёный текст | B20: Ссылка на другой лист
A21: Жёлтый фон | B21: Ключевая ассумпция — внимание
A23: ТРИ СЦЕНАРИЯ
A24: Bootstrap | B24: Без внешнего раунда. Founder-funded ~30M ₽. 7 FTE EOY. Маркетинг 12M ₽/год. ~400 сделок Y1
A25: Seed | B25: Раунд ~180M ₽. 15 FTE EOY. Маркетинг 60M ₽/год. ~750 сделок Y1
A26: Aggressive | B26: Pre-Seed + Seed ~350M ₽. 22 FTE EOY. Маркетинг 140M ₽/год. ~1 200 сделок Y1
A28: МЕТОДОЛОГИЯ
A29: Воронка | B29: Visitor → Sign-up → Activation → Qualified → Reservation → Close (5-этапная)
A30: Выручка / close | B30: ASP × 3% gross commission - 1% сертификат покупателю + adjacent services
A31: OpEx | B31: Payroll (с 30% страх.) + Marketing + Tech infra + Legal/GR + Office + Travel
A32: Founder comp | B32: Bootstrap: 200K ₽/мес deferred. Seed: 400K ₽/мес. Aggressive: 500K ₽/мес
A33: Tech-команда | B33: Claude как primary engineer. Human seniors: Bootstrap 0-1, Seed 2, Aggressive 6
A35: РЕКОМЕНДАЦИЯ | B35: См. лист Cap Table — финансовый расчёт против стратегического risk-reward

Sheet Inputs
A1: INPUTS — Ассумпции (3 сценария)
A3: Метрика | B3: Bootstrap | C3: Seed | D3: Aggressive | E3: Источник / комментарий
A4: ФИНАНСИРОВАНИЕ
A5: Cash injection / раунд (₽) | B5: 30000000 | C5: 180000000 | D5: 350000000 | E5: Founder-funded / Seed / Pre+Seed
A6: Equity дилюция (%) | B6: 0 | C6: 0.18 | D6: 0.3 | E6: Bootstrap = 0 (founders own 100%)
A7: Pre-money valuation (₽) | B7: 0 | C7: 820000000 | D7: 820000000 | E7: Seed/Aggressive ~ $10M pre-money
A9: СТРУКТУРА ВЫРУЧКИ
A10: Avg цена сделки Year 1 (₽) | B10: 14000000 | C10: 14000000 | D10: 14000000 | E10: Из v2.0 — blended апарты+квартиры+виллы Крым
A11: Gross commission rate (%) | B11: 0.03 | C11: 0.03 | D11: 0.03 | E11: Стандарт договора по ст. 1005 ГК РФ
A12: Сертификат покупателю (% от цены) | B12: 0.01 | C12: 0.01 | D12: 0.01 | E12: Защитный механизм — clawback из comm.
A13: Net core revenue / close (₽) | B13: =B10*B11-B10*B12 -> 280000 | C13: =C10*C11-C10*C12 -> 280000 | D13: =D10*D11-D10*D12 -> 280000 | E13: Computed: ASP × (gross% - cert%)
A14: Adjacent services / close Year 1 (₽) | B14: 50000 | C14: 80000 | D14: 100000 | E14: Yield mgmt, ипотечный broker, юр.док
A16: ВОРОНКА YEAR 1 (target EOY = декабрь)
A17: Visitors / month (Dec Y1) | B17: 20000 | C17: 40000 | D17: 70000 | E17: Ramp от 5K в Январе. Target Dec Y1
A18: Sign-up rate (%) | B18: 0.1 | C18: 0.12 | D18: 0.13 | E18: Apartsales benchmark — премиум аудитория
A19: Activation rate (%) | B19: 0.3 | C19: 0.35 | D19: 0.38 | E19: % sign-up which engages AI-консьерж
A20: Qualified rate (%) | B20: 0.22 | C20: 0.25 | D20: 0.28 | E20: % activated которые проходят KYC + бюджет ОК
A21: Reservation rate (%) | B21: 0.55 | C21: 0.6 | D21: 0.65 | E21: % qualified booking show / SMS-фиксация
A22: Closing rate (%) | B22: 0.2 | C22: 0.23 | D22: 0.25 | E22: % reservation → подписан ДДУ
A24: RAMP-ПРОФИЛЬ Year 1
A25: Visitors month 1 (Jan) | B25: 3000 | C25: 8000 | D25: 15000 | E25: Старт после soft-launch
A26: Linear ramp factor (Jan→Dec) | B26: 6.7 | C26: 5 | D26: 4.7 | E26: Visitors_Dec / Visitors_Jan
A28: HEADCOUNT — целевые EOY (FTE)
A29: Founders | B29: 2 | C29: 2 | D29: 2 | E29: Ты + ко-фаундер
A30: Engineering (senior humans) | B30: 1 | C30: 2 | D30: 6 | E30: + Claude как primary engineer (zero salary)
A31: AI/ML specialists | B31: 0 | C31: 1 | D31: 2 | E31: Prompt eng + model fine-tuning
A32: BD / Sales (developer outreach) | B32: 1 | C32: 3 | D32: 4 | E32: Партнёрство с застройщиками
A33: Marketing / Content | B33: 1 | C33: 2 | D33: 3 | E33: Telegram, YouTube, SEO
A34: Customer Success / AI supervisor | B34: 1 | C34: 2 | D34: 3 | E34: Поддержка покупателей
A35: Designer | B35: 0 | C35: 1 | D35: 1 | E35: Bootstrap = freelance
A36: Legal / Compliance / GR | B36: 1 | C36: 1 | D36: 1 | E36: Договоры, anti-leakage
A37: Finance / Ops | B37: 0 | C37: 1 | D37: 1 | E37: Bootstrap = founder + бухгалтер outsource
A38: HR / People | B38: 0 | C38: 0 | D38: 1 | E38: Только в Aggressive с 22 FTE
A39: ИТОГО FTE EOY | B39: =SUM(B29:B38) -> 7 | C39: =SUM(C29:C38) -> 15 | D39: =SUM(D29:D38) -> 24
A41: ЗАРПЛАТЫ РФ 2026 (gross ₽/мес на 1 FTE) + 30% страховых = total cost
A42: Founder | B42: 200000 | C42: 400000 | D42: 500000 | E42: Bootstrap: deferred. Seed/Agg: market-aligned
A43: Senior engineer | B43: 350000 | C43: 380000 | D43: 400000 | E43: Senior full-stack РФ 2026
A44: AI/ML specialist | B44: 400000 | C44: 450000 | D44: 500000 | E44: Prompt eng + ML
A45: BD / Sales | B45: 220000 | C45: 250000 | D45: 280000 | E45: + commission 5% от revenue (см. отдельно)
A46: Marketing / Content | B46: 200000 | C46: 250000 | D46: 280000 | E46: Senior content lead
...

Sheet Headcount
A1: HEADCOUNT — План найма по месяцам (FTE on payroll)
A3: Роль | B3: Jan | C3: Feb | D3: Mar | E3: Apr | F3: May | G3: Jun | H3: Jul | I3: Aug | J3: Sep | K3: Oct | L3: Nov | M3: Dec | N3: EOY
A4: Bootstrap
A5: Founders | B5: 2 | C5: 2 | D5: 2 | E5: 2 | F5: 2 | G5: 2 | H5: 2 | I5: 2 | J5: 2 | K5: 2 | L5: 2 | M5: 2 | N5: =M5 -> 2
A6: Senior engineer | I6: 1 | J6: 1 | K6: 1 | L6: 1 | M6: 1 | N6: =M6 -> 1
A7: AI/ML | N7: =M7 -> 0
A8: BD / Sales | C8: 1 | D8: 1 | E8: 1 | F8: 1 | G8: 1 | H8: 1 | I8: 1 | J8: 1 | K8: 1 | L8: 1 | M8: 1 | N8: =M8 -> 1
A9: Marketing | D9: 1 | E9: 1 | F9: 1 | G9: 1 | H9: 1 | I9: 1 | J9: 1 | K9: 1 | L9: 1 | M9: 1 | N9: =M9 -> 1
A10: Customer Success | G10: 1 | H10: 1 | I10: 1 | J10: 1 | K10: 1 | L10: 1 | M10: 1 | N10: =M10 -> 1
A11: Designer | N11: =M11 -> 0
A12: Legal / GR | B12: 1 | C12: 1 | D12: 1 | E12: 1 | F12: 1 | G12: 1 | H12: 1 | I12: 1 | J12: 1 | K12: 1 | L12: 1 | M12: 1 | N12: =M12 -> 1
A13: Finance / Ops | N13: =M13 -> 0
A14: HR / People | N14: =M14 -> 0
A15: ИТОГО Bootstrap | B15: =SUM(B5:B14) -> 3 | C15: =SUM(C5:C14) -> 4 | D15: =SUM(D5:D14) -> 5 | E15: =SUM(E5:E14) -> 5 | F15: =SUM(F5:F14) -> 5 | G15: =SUM(G5:G14) -> 6 | H15: =SUM(H5:H14) -> 6 | I15: =SUM(I5:I14) -> 7 | ... M15: =SUM(M5:M14) -> 7 | N15: =M15 -> 7
A17: Seed
A18: Founders | B18: 2 | C18: 2 | D18: 2 | E18: 2 | F18: 2 | G18: 2 | H18: 2 | I18: 2 | J18: 2 | K18: 2 | L18: 2 | M18: 2 | N18: =M18 -> 2
A19: Senior engineer | C19: 1 | D19: 1 | E19: 1 | F19: 2 | G19: 2 | H19: 2 | I19: 2 | J19: 2 | K19: 2 | L19: 2 | M19: 2 | N19: =M19 -> 2
A20: AI/ML | D20: 1 | E20: 1 | F20: 1 | G20: 1 | H20: 1 | I20: 1 | J20: 1 | K20: 1 | L20: 1 | M20: 1 | N20: =M20 -> 1
A21: BD / Sales | B21: 1 | C21: 1 | D21: 2 | E21: 2 | F21: 2 | G21: 2 | H21: 3 | I21: 3 | J21: 3 | K21: 3 | L21: 3 | M21: 3 | N21: =M21 -> 3
A22: Marketing | C22: 1 | D22: 1 | E22: 1 | F22: 1 | G22: 2 | H22: 2 | I22: 2 | J22: 2 | K22: 2 | L22: 2 | M22: 2 | N22: =M22 -> 2
A23: Customer Success | E23: 1 | F23: 1 | G23: 1 | H23: 1 | I23: 1 | J23: 2 | K23: 2 | L23: 2 | M23: 2 | N23: =M23 -> 2
A24: Designer | C24: 1 | D24: 1 | E24: 1 | F24: 1 | G24: 1 | H24: 1 | I24: 1 | J24: 1 | K24: 1 | L24: 1 | M24: 1 | N24: =M24 -> 1
A25: Legal / GR | B25: 1 | C25: 1 | D25: 1 | E25: 1 | F25: 1 | G25: 1 | H25: 1 | I25: 1 | J25: 1 | K25: 1 | L25: 1 | M25: 1 | N25: =M25 -> 1
A26: Finance / Ops | F26: 1 | G26: 1 | H26: 1 | I26: 1 | J26: 1 | K26: 1 | L26: 1 | M26: 1 | N26: =M26 -> 1
A27: HR / People | N27: =M27 -> 0
A28: ИТОГО Seed | B28: =SUM(B18:B27) -> 4 | C28: =SUM(C18:C27) -> 7 | D28: =SUM(D18:D27) -> 9 | E28: =SUM(E18:E27) -> 10 | F28: =SUM(F18:F27) -> 12 | G28: =SUM(G18:G27) -> 13 | H28: =SUM(H18:H27) -> 14 | I28: =SUM(I18:I27) -> 14 | ... M28: =SUM(M18:M27) -> 15 | N28: =M28 -> 15
A30: Aggressive
A31: Founders | B31: 2 | C31: 2 | D31: 2 | E31: 2 | F31: 2 | G31: 2 | H31: 2 | I31: 2 | J31: 2 | K31: 2 | L31: 2 | M31: 2 | N31: =M31 -> 2
A32: Senior engineer | B32: 1 | C32: 2 | D32: 3 | E32: 3 | F32: 4 | G32: 4 | H32: 5 | I32: 5 | J32: 6 | K32: 6 | L32: 6 | M32: 6 | N32: =M32 -> 6
A33: AI/ML | C33: 1 | D33: 1 | E33: 1 | F33: 2 | G33: 2 | H33: 2 | I33: 2 | J33: 2 | K33: 2 | L33: 2 | M33: 2 | N33: =M33 -> 2
A34: BD / Sales | B34: 1 | C34: 2 | D34: 2 | E34: 3 | F34: 3 | G34: 3 | H34: 4 | I34: 4 | J34: 4 | K34: 4 | L34: 4 | M34: 4 | N34: =M34 -> 4
A35: Marketing | B35: 1 | C35: 1 | D35: 2 | E35: 2 | F35: 2 | G35: 3 | H35: 3 | I35: 3 | J35: 3 | K35: 3 | L35: 3 | M35: 3 | N35: =M35 -> 3
A36: Customer Success | D36: 1 | E36: 1 | F36: 1 | G36: 2 | H36: 2 | I36: 2 | J36: 3 | K36: 3 | L36: 3 | M36: 3 | N36: =M36 -> 3
A37: Designer | B37: 1 | C37: 1 | D37: 1 | E37: 1 | F37: 1 | G37: 1 | H37: 1 | I37: 1 | J37: 1 | K37: 1 | L37: 1 | M37: 1 | N37: =M37 -> 1
A38: Legal / GR | B38: 1 | C38: 1 | D38: 1 | E38: 1 | F38: 1 | G38: 1 | H38: 1 | I38: 1 | J38: 1 | K38: 1 | L38: 1 | M38: 1 | N38: =M38 -> 1
A39: Finance / Ops | D39: 1 | E39: 1 | F39: 1 | G39: 1 | H39: 1 | I39: 1 | J39: 1 | K39: 1 | L39: 1 | M39: 1 | N39: =M39 -> 1
A40: HR / People | I40: 1 | J40: 1 | K40: 1 | L40: 1 | M40: 1 | N40: =M40 -> 1
A41: ИТОГО Aggressive | B41: =SUM(B31:B40) -> 7 | C41: =SUM(C31:C40) -> 10 | D41: =SUM(D31:D40) -> 14 | E41: =SUM(E31:E40) -> 15 | F41: =SUM(F31:F40) -> 17 | G41: =SUM(G31:G40) -> 19 | H41: =SUM(H31:H40) -> 21 | I41: =SUM(I31:I40) -> 22 | ... M41: =SUM(M31:M40) -> 24 | N41: =M41 -> 24

Sheet Revenue
A1: REVENUE BUILD — Year 1 помесячный по 3 сценариям
A3: Метрика | B3: Jan | C3: Feb | D3: Mar | E3: Apr | F3: May | G3: Jun | H3: Jul | I3: Aug | J3: Sep | K3: Oct | L3: Nov | M3: Dec | N3: Year 1 Total
A4: Bootstrap
A5: Visitors | B5: =ROUND(Inputs!B25+(Inputs!B17-Inputs!B25)*(0/11),0) -> 3000 | C5: =ROUND(Inputs!B25+(Inputs!B17-Inputs!B25)*(1/11),0) -> 4545 | D5: =ROUND(Inputs!B25+(Inputs!B17-Inputs!B25)*(2/11),0) -> 6091 | E5: =ROUND(Inputs!B25+(Inputs!B17-Inputs!B25)*(3/11),0) -> 7636 | F5: =ROUND(Inputs!B25+(Inputs!B17-Inputs!B25)*(4/11),0) -> 9182 | G5: =ROUND(Inputs!B25+(Inputs!B17-Inputs!B25)*(5/11),0) -> 10727 | H5: =ROUND(Inputs!B25+(Inputs!B17-Inputs!B25)*(6/11),0) -> 12273 | I5: =ROUND(Inputs!B25+(Inputs!B17-Inputs!B25)*(7/11),0) -> 13818 | J5: =ROUND(Inputs!B25+(Inputs!B17-Inputs!B25)*(8/11),0) -> 15364 | K5: =ROUND(Inputs!B25+(Inputs!B17-Inputs!B25)*(9/11),0) -> 16909 | L5: =ROUND(Inputs!B25+(Inputs!B17-Inputs!B25)*(10/11),0) -> 18455 | M5: =ROUND(Inputs!B25+(Inputs!B17-Inputs!B25)*(11/11),0) -> 20000 | N5: =SUM(B5:M5) -> 138000
A6: Sign-ups | B6: =ROUND(B5*Inputs!B18,0) -> 300 | C6: =ROUND(C5*Inputs!B18,0) -> 455 | D6: =ROUND(D5*Inputs!B18,0) -> 609 | E6: =ROUND(E5*Inputs!B18,0) -> 764 | F6: =ROUND(F5*Inputs!B18,0) -> 918 | G6: =ROUND(G5*Inputs!B18,0) -> 1073 | H6: =ROUND(H5*Inputs!B18,0) -> 1227 | I6: =ROUND(I5*Inputs!B18,0) -> 1382 | J6: =ROUND(J5*Inputs!B18,0) -> 1536 | K6: =ROUND(K5*Inputs!B18,0) -> 1691 | L6: =ROUND(L5*Inputs!B18,0) -> 1846 | M6: =ROUND(M5*Inputs!B18,0) -> 2000 | N6: =SUM(B6:M6) -> 13801
A7: Activated | B7: =ROUND(B6*Inputs!B19,0) -> 90 | C7: =ROUND(C6*Inputs!B19,0) -> 137 | D7: =ROUND(D6*Inputs!B19,0) -> 183 | E7: =ROUND(E6*Inputs!B19,0) -> 229 | F7: =ROUND(F6*Inputs!B19,0) -> 275 | G7: =ROUND(G6*Inputs!B19,0) -> 322 | H7: =ROUND(H6*Inputs!B19,0) -> 368 | I7: =ROUND(I6*Inputs!B19,0) -> 415 | J7: =ROUND(J6*Inputs!B19,0) -> 461 | K7: =ROUND(K6*Inputs!B19,0) -> 507 | L7: =ROUND(L6*Inputs!B19,0) -> 554 | M7: =ROUND(M6*Inputs!B19,0) -> 600 | N7: =SUM(B7:M7) -> 4141
A8: Qualified | B8: =ROUND(B7*Inputs!B20,0) -> 20 | C8: =ROUND(C7*Inputs!B20,0) -> 30 | D8: =ROUND(D7*Inputs!B20,0) -> 40 | E8: =ROUND(E7*Inputs!B20,0) -> 50 | F8: =ROUND(F7*Inputs!B20,0) -> 61 | G8: =ROUND(G7*Inputs!B20,0) -> 71 | H8: =ROUND(H7*Inputs!B20,0) -> 81 | I8: =ROUND(I7*Inputs!B20,0) -> 91 | J8: =ROUND(J7*Inputs!B20,0) -> 101 | K8: =ROUND(K7*Inputs!B20,0) -> 112 | L8: =ROUND(L7*Inputs!B20,0) -> 122 | M8: =ROUND(M7*Inputs!B20,0) -> 132 | N8: =SUM(B8:M8) -> 911
A9: Reservations (lead lock) | B9: =ROUND(B8*Inputs!B21,0) -> 11 | C9: =ROUND(C8*Inputs!B21,0) -> 17 | D9: =ROUND(D8*Inputs!B21,0) -> 22 | E9: =ROUND(E8*Inputs!B21,0) -> 28 | F9: =ROUND(F8*Inputs!B21,0) -> 34 | G9: =ROUND(G8*Inputs!B21,0) -> 39 | H9: =ROUND(H8*Inputs!B21,0) -> 45 | I9: =ROUND(I8*Inputs!B21,0) -> 50 | J9: =ROUND(J8*Inputs!B21,0) -> 56 | K9: =ROUND(K8*Inputs!B21,0) -> 62 | L9: =ROUND(L8*Inputs!B21,0) -> 67 | M9: =ROUND(M8*Inputs!B21,0) -> 73 | N9: =SUM(B9:M9) -> 504
A10: Closes (с лагом 1.5 мес) | B10: =0 -> 0 | C10: =ROUND(B9*Inputs!B22,0) -> 2 | D10: =ROUND(C9*Inputs!B22,0) -> 3 | E10: =ROUND(D9*Inputs!B22,0) -> 4 | F10: =ROUND(E9*Inputs!B22,0) -> 6 | G10: =ROUND(F9*Inputs!B22,0) -> 7 | H10: =ROUND(G9*Inputs!B22,0) -> 8 | I10: =ROUND(H9*Inputs!B22,0) -> 9 | J10: =ROUND(I9*Inputs!B22,0) -> 10 | K10: =ROUND(J9*Inputs!B22,0) -> 11 | L10: =ROUND(K9*Inputs!B22,0) -> 12 | M10: =ROUND(L9*Inputs!B22,0) -> 13 | N10: =SUM(B10:M10) -> 85
A11: Revenue (₽) | B11: =B10*Inputs!B73 -> 0 | C11: =C10*Inputs!B73 -> 660000 | D11: =D10*Inputs!B73 -> 990000 | E11: =E10*Inputs!B73 -> 1320000 | F11: =F10*Inputs!B73 -> 1980000 | G11: =G10*Inputs!B73 -> 2310000 | H11: =H10*Inputs!B73 -> 2640000 | I11: =I10*Inputs!B73 -> 2970000 | J11: =J10*Inputs!B73 -> 3300000 | K11: =K10*Inputs!B73 -> 3630000 | L11: =L10*Inputs!B73 -> 3960000 | M11: =M10*Inputs!B73 -> 4290000 | N11: =SUM(B11:M11) -> 28050000
A13: Seed
A14: Visitors | B14: =ROUND(Inputs!C25+(Inputs!C17-Inputs!C25)*(0/11),0) -> 8000 | C14: =ROUND(Inputs!C25+(Inputs!C17-Inputs!C25)*(1/11),0) -> 10909 | D14: =ROUND(Inputs!C25+(Inputs!C17-Inputs!C25)*(2/11),0) -> 13818 | E14: =ROUND(Inputs!C25+(Inputs!C17-Inputs!C25)*(3/11),0) -> 16727 | F14: =ROUND(Inputs!C25+(Inputs!C17-Inputs!C25)*(4/11),0) -> 19636 | G14: =ROUND(Inputs!C25+(Inputs!C17-Inputs!C25)*(5/11),0) -> 22545 | H14: =ROUND(Inputs!C25+(Inputs!C17-Inputs!C25)*(6/11),0) -> 25455 | I14: =ROUND(Inputs!C25+(Inputs!C17-Inputs!C25)*(7/11),0) -> 28364 | J14: =ROUND(Inputs!C25+(Inputs!C17-Inputs!C25)*(8/11),0) -> 31273 | K14: =ROUND(Inputs!C25+(Inputs!C17-Inputs!C25)*(9/11),0) -> 34182 | L14: =ROUND(Inputs!C25+(Inputs!C17-Inputs!C25)*(10/11),0) -> 37091 | M14: =ROUND(Inputs!C25+(Inputs!C17-Inputs!C25)*(11/11),0) -> 40000 | N14: =SUM(B14:M14) -> 288000
A15: Sign-ups | B15: =ROUND(B14*Inputs!C18,0) -> 960 | C15: =ROUND(C14*Inputs!C18,0) -> 1309 | D15: =ROUND(D14*Inputs!C18,0) -> 1658 | E15: =ROUND(E14*Inputs!C18,0) -> 2007 | F15: =ROUND(F14*Inputs!C18,0) -> 2356 | G15: =ROUND(G14*Inputs!C18,0) -> 2705 | H15: =ROUND(H14*Inputs!C18,0) -> 3055 | I15: =ROUND(I14*Inputs!C18,0) -> 3404 | J15: =ROUND(J14*Inputs!C18,0) -> 3753 | K15: =ROUND(K14*Inputs!C18,0) -> 4102 | L15: =ROUND(L14*Inputs!C18,0) -> 4451 | M15: =ROUND(M14*Inputs!C18,0) -> 4800 | N15: =SUM(B15:M15) -> 34560
A16: Activated | B16: =ROUND(B15*Inputs!C19,0) -> 336 | C16: =ROUND(C15*Inputs!C19,0) -> 458 | D16: =ROUND(D15*Inputs!C19,0) -> 580 | E16: =ROUND(E15*Inputs!C19,0) -> 702 | F16: =ROUND(F15*Inputs!C19,0) -> 825 | G16: =ROUND(G15*Inputs!C19,0) -> 947 | H16: =ROUND(H15*Inputs!C19,0) -> 1069 | I16: =ROUND(I15*Inputs!C19,0) -> 1191 | J16: =ROUND(J15*Inputs!C19,0) -> 1314 | K16: =ROUND(K15*Inputs!C19,0) -> 1436 | L16: =ROUND(L15*Inputs!C19,0) -> 1558 | M16: =ROUND(M15*Inputs!C19,0) -> 1680 | N16: =SUM(B16:M16) -> 12096
A17: Qualified | B17: =ROUND(B16*Inputs!C20,0) -> 84 | C17: =ROUND(C16*Inputs!C20,0) -> 115 | D17: =ROUND(D16*Inputs!C20,0) -> 145 | E17: =ROUND(E16*Inputs!C20,0) -> 176 | F17: =ROUND(F16*Inputs!C20,0) -> 206 | G17: =ROUND(G16*Inputs!C20,0) -> 237 | H17: =ROUND(H16*Inputs!C20,0) -> 267 | I17: =ROUND(I16*Inputs!C20,0) -> 298 | J17: =ROUND(J16*Inputs!C20,0) -> 329 | K17: =ROUND(K16*Inputs!C20,0) -> 359 | L17: =ROUND(L16*Inputs!C20,0) -> 390 | M17: =ROUND(M16*Inputs!C20,0) -> 420 | N17: =SUM(B17:M17) -> 3026
A18: Reservations (lead lock) | B18: =ROUND(B17*Inputs!C21,0) -> 50 | C18: =ROUND(C17*Inputs!C21,0) -> 69 | D18: =ROUND(D17*Inputs!C21,0) -> 87 | E18: =ROUND(E17*Inputs!C21,0) -> 106 | F18: =ROUND(F17*Inputs!C21,0) -> 124 | G18: =ROUND(G17*Inputs!C21,0) -> 142 | H18: =ROUND(H17*Inputs!C21,0) -> 160 | I18: =ROUND(I17*Inputs!C21,0) -> 179 | J18: =ROUND(J17*Inputs!C21,0) -> 197 | K18: =ROUND(K17*Inputs!C21,0) -> 215 | L18: =ROUND(L17*Inputs!C21,0) -> 234 | M18: =ROUND(M17*Inputs!C21,0) -> 252 | N18: =SUM(B18:M18) -> 1815
A19: Closes (с лагом 1.5 мес) | B19: =0 -> 0 | C19: =ROUND(B18*Inputs!C22,0) -> 12 | D19: =ROUND(C18*Inputs!C22,0) -> 16 | E19: =ROUND(D18*Inputs!C22,0) -> 20 | F19: =ROUND(E18*Inputs!C22,0) -> 24 | G19: =ROUND(F18*Inputs!C22,0) -> 29 | H19: =ROUND(G18*Inputs!C22,0) -> 33 | I19: =ROUND(H18*Inputs!C22,0) -> 37 | J19: =ROUND(I18*Inputs!C22,0) -> 41 | K19: =ROUND(J18*Inputs!C22,0) -> 45 | L19: =ROUND(K18*Inputs!C22,0) -> 49 | M19: =ROUND(L18*Inputs!C22,0) -> 54 | N19: =SUM(B19:M19) -> 360
A20: Revenue (₽) | B20: =B19*Inputs!C73 -> 0 | C20: =C19*Inputs!C73 -> 4320000 | D20: =D19*Inputs!C73 -> 5760000 | E20: =E19*Inputs!C73 -> 7200000 | F20: =F19*Inputs!C73 -> 8640000 | G20: =G19*Inputs!C73 -> 10440000 | H20: =H19*Inputs!C73 -> 11880000 | I20: =I19*Inputs!C73 -> 13320000 | J20: =J19*Inputs!C73 -> 14760000 | K20: =K19*Inputs!C73 -> 16200000 | L20: =L19*Inputs!C73 -> 17640000 | M20: =M19*Inputs!C73 -> 19440000 | N20: =SUM(B20:M20) -> 129600000
A22: Aggressive
A23: Visitors | B23: =ROUND(Inputs!D25+(Inputs!D17-Inputs!D25)*(0/11),0) -> 15000 | C23: =ROUND(Inputs!D25+(Inputs!D17-Inputs!D25)*(1/11),0) -> 20000 | D23: =ROUND(Inputs!D25+(Inputs!D17-Inputs!D25)*(2/11),0) -> 25000 | E23: =ROUND(Inputs!D25+(Inputs!D17-Inputs!D25)*(3/11),0) -> 30000 | F23: =ROUND(Inputs!D25+(Inputs!D17-Inputs!D25)*(4/11),0) -> 35000 | G23: =ROUND(Inputs!D25+(Inputs!D17-Inputs!D25)*(5/11),0) -> 40000 | H23: =ROUND(Inputs!D25+(Inputs!D17-Inputs!D25)*(6/11),0) -> 45000 | I23: =ROUND(Inputs!D25+(Inputs!D17-Inputs!D25)*(7/11),0) -> 50000 | J23: =ROUND(Inputs!D25+(Inputs!D17-Inputs!D25)*(8/11),0) -> 55000 | K23: =ROUND(Inputs!D25+(Inputs!D17-Inputs!D25)*(9/11),0) -> 60000 | L23: =ROUND(Inputs!D25+(Inputs!D17-Inputs!D25)*(10/11),0) -> 65000 | M23: =ROUND(Inputs!D25+(Inputs!D17-Inputs!D25)*(11/11),0) -> 70000 | N23: =SUM(B23:M23) -> 510000
A24: Sign-ups | B24: =ROUND(B23*Inputs!D18,0) -> 1950 | C24: =ROUND(C23*Inputs!D18,0) -> 2600 | D24: =ROUND(D23*Inputs!D18,0) -> 3250 | E24: =ROUND(E23*Inputs!D18,0) -> 3900 | F24: =ROUND(F23*Inputs!D18,0) -> 4550 | G24: =ROUND(G23*Inputs!D18,0) -> 5200 | H24: =ROUND(H23*Inputs!D18,0) -> 5850 | I24: =ROUND(I23*Inputs!D18,0) -> 6500 | J24: =ROUND(J23*Inputs!D18,0) -> 7150 | K24: =ROUND(K23*Inputs!D18,0) -> 7800 | L24: =ROUND(L23*Inputs!D18,0) -> 8450 | M24: =ROUND(M23*Inputs!D18,0) -> 9100 | N24: =SUM(B24:M24) -> 66300
A25: Activated | B25: =ROUND(B24*Inputs!D19,0) -> 741 | C25: =ROUND(C24*Inputs!D19,0) -> 988 | D25: =ROUND(D24*Inputs!D19,0) -> 1235 | E25: =ROUND(E24*Inputs!D19,0) -> 1482 | F25: =ROUND(F24*Inputs!D19,0) -> 1729 | G25: =ROUND(G24*Inputs!D19,0) -> 1976 | H25: =ROUND(H24*Inputs!D19,0) -> 2223 | I25: =ROUND(I24*Inputs!D19,0) -> 2470 | J25: =ROUND(J24*Inputs!D19,0) -> 2717 | K25: =ROUND(K24*Inputs!D19,0) -> 2964 | L25: =ROUND(L24*Inputs!D19,0) -> 3211 | M25: =ROUND(M24*Inputs!D19,0) -> 3458 | N25: =SUM(B25:M25) -> 25194
A26: Qualified | B26: =ROUND(B25*Inputs!D20,0) -> 207 | C26: =ROUND(C25*Inputs!D20,0) -> 277 | D26: =ROUND(D25*Inputs!D20,0) -> 346 | E26: =ROUND(E25*Inputs!D20,0) -> 415 | F26: =ROUND(F25*Inputs!D20,0) -> 484 | G26: =ROUND(G25*Inputs!D20,0) -> 553 | H26: =ROUND(H25*Inputs!D20,0) -> 622 | I26: =ROUND(I25*Inputs!D20,0) -> 692 | J26: =ROUND(J25*Inputs!D20,0) -> 761 | K26: =ROUND(K25*Inputs!D20,0) -> 830 | L26: =ROUND(L25*Inputs!D20,0) -> 899 | M26: =ROUND(M25*Inputs!D20,0) -> 968 | N26: =SUM(B26:M26) -> 7054
A27: Reservations (lead lock) | B27: =ROUND(B26*Inputs!D21,0) -> 135 | C27: =ROUND(C26*Inputs!D21,0) -> 180 | D27: =ROUND(D26*Inputs!D21,0) -> 225 | E27: =ROUND(E26*Inputs!D21,0) -> 270 | F27: =ROUND(F26*Inputs!D21,0) -> 315 | G27: =ROUND(G26*Inputs!D21,0) -> 359 | H27: =ROUND(H26*Inputs!D21,0) -> 404 | I27: =ROUND(I26*Inputs!D21,0) -> 450 | J27: =ROUND(J26*Inputs!D21,0) -> 495 | K27: =ROUND(K26*Inputs!D21,0) -> 540 | L27: =ROUND(L26*Inputs!D21,0) -> 584 | M27: =ROUND(M26*Inputs!D21,0) -> 629 | N27: =SUM(B27:M27) -> 4586
A28: Closes (с лагом 1.5 мес) | B28: =0 -> 0 | C28: =ROUND(B27*Inputs!D22,0) -> 34 | D28: =ROUND(C27*Inputs!D22,0) -> 45 | E28: =ROUND(D27*Inputs!D22,0) -> 56 | F28: =ROUND(E27*Inputs!D22,0) -> 68 | G28: =ROUND(F27*Inputs!D22,0) -> 79 | H28: =ROUND(G27*Inputs!D22,0) -> 90 | I28: =ROUND(H27*Inputs!D22,0) -> 101 | J28: =ROUND(I27*Inputs!D22,0) -> 113 | K28: =ROUND(J27*Inputs!D22,0) -> 124 | L28: =ROUND(K27*Inputs!D22,0) -> 135 | M28: =ROUND(L27*Inputs!D22,0) -> 146 | N28: =SUM(B28:M28) -> 991
A29: Revenue (₽) | B29: =B28*Inputs!D73 -> 0 | C29: =C28*Inputs!D73 -> 12920000 | D29: =D28*Inputs!D73 -> 17100000 | E29: =E28*Inputs!D73 -> 21280000 | F29: =F28*Inputs!D73 -> 25840000 | G29: =G28*Inputs!D73 -> 30020000 | H29: =H28*Inputs!D73 -> 34200000 | I29: =I28*Inputs!D73 -> 38380000 | J29: =J28*Inputs!D73 -> 42940000 | K29: =K28*Inputs!D73 -> 47120000 | L29: =L28*Inputs!D73 -> 51300000 | M29: =M28*Inputs!D73 -> 55480000 | N29: =SUM(B29:M29) -> 376580000

Sheet P&L Year 1
A1: P&L YEAR 1 — Помесячный (3 сценария)
A3: Метрика | B3: Jan | C3: Feb | D3: Mar | E3: Apr | F3: May | G3: Jun | H3: Jul | I3: Aug | J3: Sep | K3: Oct | L3: Nov | M3: Dec | N3: Year 1 Total
A4: Bootstrap
A5: Revenue | B5: =Revenue!B11 -> 0 | C5: =Revenue!C11 -> 660000 | D5: =Revenue!D11 -> 990000 | E5: =Revenue!E11 -> 1320000 | F5: =Revenue!F11 -> 1980000 | G5: =Revenue!G11 -> 2310000 | H5: =Revenue!H11 -> 2640000 | I5: =Revenue!I11 -> 2970000 | ... N5: =Revenue!N11 -> 28050000
A7: OPEX:
A8: Payroll (с 30% страховых) | B8: =SUMPRODUCT(Headcount!B5:B14,Inputs!$B$42:$B$51)*Inputs!$B$52 -> 884000 | C8: =SUMPRODUCT(Headcount!C5:C14,Inputs!$B$42:$B$51)*Inputs!$B$52 -> 1170000 | D8: =SUMPRODUCT(Headcount!D5:D14,Inputs!$B$42:$B$51)*Inputs!$B$52 -> 1430000 | E8: =SUMPRODUCT(Headcount!E5:E14,Inputs!$B$42:$B$51)*Inputs!$B$52 -> 1430000 | F8: =SUMPRODUCT(Headcount!F5:F14,Inputs!$B$42:$B$51)*Inputs!$B$52 -> 1430000 | G8: =SUMPRODUCT(Headcount!G5:G14,Inputs!$B$42:$B$51)*Inputs!$B$52 -> 1625000 | H8: =SUMPRODUCT(Headcount!H5:H14,Inputs!$B$42:$B$51)*Inputs!$B$52 -> 1625000 | I8: =SUMPRODUCT(Headcount!I5:I14,Inputs!$B$42:$B$51)*Inputs!$B$52 -> 2080000 | ... M8: =SUMPRODUCT(Headcount!M5:M14,Inputs!$B$42:$B$51)*Inputs!$B$52 -> 2080000 | N8: =SUM(B8:M8) -> 19994000
A9: Marketing & acquisition | B9: =Inputs!$B$55/12 -> 1000000 | C9: =Inputs!$B$55/12 -> 1000000 | D9: =Inputs!$B$55/12 -> 1000000 | E9: =Inputs!$B$55/12 -> 1000000 | F9: =Inputs!$B$55/12 -> 1000000 | G9: =Inputs!$B$55/12 -> 1000000 | H9: =Inputs!$B$55/12 -> 1000000 | I9: =Inputs!$B$55/12 -> 1000000 | ... M9: =Inputs!$B$55/12 -> 1000000 | N9: =Inputs!$B$55 -> 12000000
A10: Tech infrastructure | B10: =Inputs!$B$63/12 -> 200000 | C10: =Inputs!$B$63/12 -> 200000 | D10: =Inputs!$B$63/12 -> 200000 | E10: =Inputs!$B$63/12 -> 200000 | F10: =Inputs!$B$63/12 -> 200000 | G10: =Inputs!$B$63/12 -> 200000 | H10: =Inputs!$B$63/12 -> 200000 | I10: =Inputs!$B$63/12 -> 200000 | ... M10: =Inputs!$B$63/12 -> 200000 | N10: =Inputs!$B$63 -> 2400000
A11: Office | B11: =Inputs!$B$65/12 -> 50000 | C11: =Inputs!$B$65/12 -> 50000 | D11: =Inputs!$B$65/12 -> 50000 | E11: =Inputs!$B$65/12 -> 50000 | F11: =Inputs!$B$65/12 -> 50000 | G11: =Inputs!$B$65/12 -> 50000 | H11: =Inputs!$B$65/12 -> 50000 | I11: =Inputs!$B$65/12 -> 50000 | ... M11: =Inputs!$B$65/12 -> 50000 | N11: =Inputs!$B$65 -> 600000
A12: Travel (Крым) | B12: =Inputs!$B$66/12 -> 125000 | C12: =Inputs!$B$66/12 -> 125000 | D12: =Inputs!$B$66/12 -> 125000 | E12: =Inputs!$B$66/12 -> 125000 | F12: =Inputs!$B$66/12 -> 125000 | G12: =Inputs!$B$66/12 -> 125000 | H12: =Inputs!$B$66/12 -> 125000 | I12: =Inputs!$B$66/12 -> 125000 | ... M12: =Inputs!$B$66/12 -> 125000 | N12: =Inputs!$B$66 -> 1500000
A13: Legal / договоры / pilots | B13: =Inputs!$B$64/12 -> 100000 | C13: =Inputs!$B$64/12 -> 100000 | D13: =Inputs!$B$64/12 -> 100000 | E13: =Inputs!$B$64/12 -> 100000 | F13: =Inputs!$B$64/12 -> 100000 | G13: =Inputs!$B$64/12 -> 100000 | H13: =Inputs!$B$64/12 -> 100000 | I13: =Inputs!$B$64/12 -> 100000 | ... M13: =Inputs!$B$64/12 -> 100000 | N13: =Inputs!$B$64 -> 1200000
A14: Бухгалтерия / outsource | B14: =Inputs!$B$67/12 -> 50000 | C14: =Inputs!$B$67/12 -> 50000 | D14: =Inputs!$B$67/12 -> 50000 | E14: =Inputs!$B$67/12 -> 50000 | F14: =Inputs!$B$67/12 -> 50000 | G14: =Inputs!$B$67/12 -> 50000 | H14: =Inputs!$B$67/12 -> 50000 | I14: =Inputs!$B$67/12 -> 50000 | ... M14: =Inputs!$B$67/12 -> 50000 | N14: =Inputs!$B$67 -> 600000
A15: Прочее / резерв | B15: =Inputs!$B$68/12 -> 83333.333 | C15: =Inputs!$B$68/12 -> 83333.333 | D15: =Inputs!$B$68/12 -> 83333.333 | E15: =Inputs!$B$68/12 -> 83333.333 | F15: =Inputs!$B$68/12 -> 83333.333 | G15: =Inputs!$B$68/12 -> 83333.333 | H15: =Inputs!$B$68/12 -> 83333.333 | I15: =Inputs!$B$68/12 -> 83333.333 | ... M15: =Inputs!$B$68/12 -> 83333.333 | N15: =Inputs!$B$68 -> 1000000
A16: BD commission (5% of revenue) | B16: =B5*0.05 -> 0 | C16: =C5*0.05 -> 33000 | D16: =D5*0.05 -> 49500 | E16: =E5*0.05 -> 66000 | F16: =F5*0.05 -> 99000 | G16: =G5*0.05 -> 115500 | H16: =H5*0.05 -> 132000 | I16: =I5*0.05 -> 148500 | ... M16: =M5*0.05 -> 214500 | N16: =SUM(B16:M16) -> 1402500
A17: Total OpEx | B17: =SUM(B8:B16) -> 2492333.3 | C17: =SUM(C8:C16) -> 2811333.3 | D17: =SUM(D8:D16) -> 3087833.3 | E17: =SUM(E8:E16) -> 3104333.3 | F17: =SUM(F8:F16) -> 3137333.3 | G17: =SUM(G8:G16) -> 3348833.3 | H17: =SUM(H8:H16) -> 3365333.3 | I17: =SUM(I8:I16) -> 3836833.3 | ... M17: =SUM(M8:M16) -> 3902833.3 | N17: =SUM(B17:M17) -> 40696500
A19: EBITDA | B19: =B5-B17 -> -2492333.3 | C19: =C5-C17 -> -2151333.3 | D19: =D5-D17 -> -2097833.3 | E19: =E5-E17 -> -1784333.3 | F19: =F5-F17 -> -1157333.3 | G19: =G5-G17 -> -1038833.3 | H19: =H5-H17 -> -725333.33 | I19: =I5-I17 -> -866833.33 | ... N19: =N5-N17 -> -12646500
A20: Cash position EOM | B20: =Inputs!$B$5+B19 -> 27507667 | C20: =B20+C19 -> 25356333 | D20: =C20+D19 -> 23258500 | E20: =D20+E19 -> 21474167 | F20: =E20+F19 -> 20316833 | G20: =F20+G19 -> 19278000 | H20: =G20+H19 -> 18552667 | I20: =H20+I19 -> 17685833 | J20: =I20+J19 -> 17132500 | ... M20: =L20+M19 -> 17353500 | N20: =M20 -> 17353500
A21: Closes / month (memo) | B21: =Revenue!B10 -> 0 | C21: =Revenue!C10 -> 2 | D21: =Revenue!D10 -> 3 | E21: =Revenue!E10 -> 4 | F21: =Revenue!F10 -> 6 | G21: =Revenue!G10 -> 7 | H21: =Revenue!H10 -> 8 | I21: =Revenue!I10 -> 9 | ... M21: =Revenue!M10 -> 13 | N21: =SUM(B21:M21) -> 85
A23: Seed
A24: Revenue | B24: =Revenue!B20 -> 0 | C24: =Revenue!C20 -> 4320000 | D24: =Revenue!D20 -> 5760000 | E24: =Revenue!E20 -> 7200000 | F24: =Revenue!F20 -> 8640000 | G24: =Revenue!G20 -> 10440000 | H24: =Revenue!H20 -> 11880000 | I24: =Revenue!I20 -> 13320000 | ... N24: =Revenue!N20 -> 129600000
A26: OPEX:
A27: Payroll (с 30% страховых) | B27: =SUMPRODUCT(Headcount!B18:B27,Inputs!$C$42:$C$51)*Inputs!$C$52 -> 1781000 | C27: =SUMPRODUCT(Headcount!C18:C27,Inputs!$C$42:$C$51)*Inputs!$C$52 -> 2925000 | D27: =SUMPRODUCT(Headcount!D18:D27,Inputs!$C$42:$C$51)*Inputs!$C$52 -> 3835000 | E27: =SUMPRODUCT(Headcount!E18:E27,Inputs!$C$42:$C$51)*Inputs!$C$52 -> 4069000 | F27: =SUMPRODUCT(Headcount!F18:F27,Inputs!$C$42:$C$51)*Inputs!$C$52 -> 4927000 | G27: =SUMPRODUCT(Headcount!G18:G27,Inputs!$C$42:$C$51)*Inputs!$C$52 -> 5252000 | H27: =SUMPRODUCT(Headcount!H18:H27,Inputs!$C$42:$C$51)*Inputs!$C$52 -> 5577000 | I27: =SUMPRODUCT(Headcount!I18:I27,Inputs!$C$42:$C$51)*Inputs!$C$52 -> 5577000 | ... M27: =SUMPRODUCT(Headcount!M18:M27,Inputs!$C$42:$C$51)*Inputs!$C$52 -> 5811000 | N27: =SUM(B27:M27) -> 57187000
A28: Marketing & acquisition | B28: =Inputs!$C$55/12 -> 5000000 | C28: =Inputs!$C$55/12 -> 5000000 | D28: =Inputs!$C$55/12 -> 5000000 | E28: =Inputs!$C$55/12 -> 5000000 | F28: =Inputs!$C$55/12 -> 5000000 | G28: =Inputs!$C$55/12 -> 5000000 | H28: =Inputs!$C$55/12 -> 5000000 | I28: =Inputs!$C$55/12 -> 5000000 | ... M28: =Inputs!$C$55/12 -> 5000000 | N28: =Inputs!$C$55 -> 60000000
A29: Tech infrastructure | B29: =Inputs!$C$63/12 -> 500000 | C29: =Inputs!$C$63/12 -> 500000 | D29: =Inputs!$C$63/12 -> 500000 | E29: =Inputs!$C$63/12 -> 500000 | F29: =Inputs!$C$63/12 -> 500000 | G29: =Inputs!$C$63/12 -> 500000 | H29: =Inputs!$C$63/12 -> 500000 | I29: =Inputs!$C$63/12 -> 500000 | ... M29: =Inputs!$C$63/12 -> 500000 | N29: =Inputs!$C$63 -> 6000000
A30: Office | B30: =Inputs!$C$65/12 -> 400000 | C30: =Inputs!$C$65/12 -> 400000 | D30: =Inputs!$C$65/12 -> 400000 | E30: =Inputs!$C$65/12 -> 400000 | F30: =Inputs!$C$65/12 -> 400000 | G30: =Inputs!$C$65/12 -> 400000 | H30: =Inputs!$C$65/12 -> 400000 | I30: =Inputs!$C$65/12 -> 400000 | ... M30: =Inputs!$C$65/12 -> 400000 | N30: =Inputs!$C$65 -> 4800000
A31: Travel (Крым) | B31: =Inputs!$C$66/12 -> 333333.33 | C31: =Inputs!$C$66/12 -> 333333.33 | D31: =Inputs!$C$66/12 -> 333333.33 | E31: =Inputs!$C$66/12 -> 333333.33 | F31: =Inputs!$C$66/12 -> 333333.33 | G31: =Inputs!$C$66/12 -> 333333.33 | H31: =Inputs!$C$66/12 -> 333333.33 | I31: =Inputs!$C$66/12 -> 333333.33 | ... M31: =Inputs!$C$66/12 -> 333333.33 | N31: =Inputs!$C$66 -> 4000000
A32: Legal / договоры / pilots | B32: =Inputs!$C$64/12 -> 250000 | C32: =Inputs!$C$64/12 -> 250000 | D32: =Inputs!$C$64/12 -> 250000 | E32: =Inputs!$C$64/12 -> 250000 | F32: =Inputs!$C$64/12 -> 250000 | G32: =Inputs!$C$64/12 -> 250000 | H32: =Inputs!$C$64/12 -> 250000 | I32: =Inputs!$C$64/12 -> 250000 | ... M32: =Inputs!$C$64/12 -> 250000 | N32: =Inputs!$C$64 -> 3000000
A33: Бухгалтерия / outsource | B33: =Inputs!$C$67/12 -> 100000 | C33: =Inputs!$C$67/12 -> 100000 | D33: =Inputs!$C$67/12 -> 100000 | E33: =Inputs!$C$67/12 -> 100000 | F33: =Inputs!$C$67/12 -> 100000 | G33: =Inputs!$C$67/12 -> 100000 | H33: =Inputs!$C$67/12 -> 100000 | I33: =Inputs!$C$67/12 -> 100000 | ... M33: =Inputs!$C$67/12 -> 100000 | N33: =Inputs!$C$67 -> 1200000
A34: Прочее / резерв | B34: =Inputs!$C$68/12 -> 250000 | C34: =Inputs!$C$68/12 -> 250000 | D34: =Inputs!$C$68/12 -> 250000 | E34: =Inputs!$C$68/12 -> 250000 | F34: =Inputs!$C$68/12 -> 250000 | G34: =Inputs!$C$68/12 -> 250000 | H34: =Inputs!$C$68/12 -> 250000 | I34: =Inputs!$C$68/12 -> 250000 | ... M34: =Inputs!$C$68/12 -> 250000 | N34: =Inputs!$C$68 -> 3000000
A35: BD commission (5% of revenue) | B35: =B24*0.05 -> 0 | C35: =C24*0.05 -> 216000 | D35: =D24*0.05 -> 288000 | E35: =E24*0.05 -> 360000 | F35: =F24*0.05 -> 432000 | G35: =G24*0.05 -> 522000 | H35: =H24*0.05 -> 594000 | I35: =I24*0.05 -> 666000 | ... M35: =M24*0.05 -> 972000 | N35: =SUM(B35:M35) -> 6480000
A36: Total OpEx | B36: =SUM(B27:B35) -> 8614333.3 | C36: =SUM(C27:C35) -> 9974333.3 | D36: =SUM(D27:D35) -> 10956333 | E36: =SUM(E27:E35) -> 11262333 | F36: =SUM(F27:F35) -> 12192333 | G36: =SUM(G27:G35) -> 12607333 | H36: =SUM(H27:H35) -> 13004333 | I36: =SUM(I27:I35) -> 13076333 | ... M36: =SUM(M27:M35) -> 13616333 | N36: =SUM(B36:M36) -> 145667000
A38: EBITDA | B38: =B24-B36 -> -8614333.3 | C38: =C24-C36 -> -5654333.3 | D38: =D24-D36 -> -5196333.3 | E38: =E24-E36 -> -4062333.3 | F38: =F24-F36 -> -3552333.3 | G38: =G24-G36 -> -2167333.3 | H38: =H24-H36 -> -1124333.3 | I38: =I24-I36 -> 243666.67 | ... N38: =N24-N36 -> -16067000
A39: Cash position EOM | B39: =Inputs!$C$5+B38 -> 1.7138567e+08 | C39: =B39+C38 -> 1.6573133e+08 | D39: =C39+D38 -> 160535000 | E39: =D39+E38 -> 1.5647267e+08 | F39: =E39+F38 -> 1.5292033e+08 | G39: =F39+G38 -> 150753000 | H39: =G39+H38 -> 1.4962867e+08 | I39: =H39+I38 -> 1.4987233e+08 | J39: =I39+J38 -> 151250000 | ... M39: =L39+M38 -> 163933000 | N39: =M39 -> 163933000
A40: Closes / month (memo) | B40: =Revenue!B19 -> 0 | C40: =Revenue!C19 -> 12 | D40: =Revenue!D19 -> 16 | E40: =Revenue!E19 -> 20 | F40: =Revenue!F19 -> 24 | G40: =Revenue!G19 -> 29 | H40: =Revenue!H19 -> 33 | I40: =Revenue!I19 -> 37 | ... M40: =Revenue!M19 -> 54 | N40: =SUM(B40:M40) -> 360
A42: Aggressive
A43: Revenue | B43: =Revenue!B29 -> 0 | C43: =Revenue!C29 -> 12920000 | D43: =Revenue!D29 -> 17100000 | E43: =Revenue!E29 -> 21280000 | F43: =Revenue!F29 -> 25840000 | G43: =Revenue!G29 -> 30020000 | H43: =Revenue!H29 -> 34200000 | I43: =Revenue!I29 -> 38380000 | ... N43: =Revenue!N29 -> 376580000
A45: OPEX:
A46: Payroll (с 30% страховых) | B46: =SUMPRODUCT(Headcount!B31:B40,Inputs!$D$42:$D$51)*Inputs!$D$52 -> 3354000 | C46: =SUMPRODUCT(Headcount!C31:C40,Inputs!$D$42:$D$51)*Inputs!$D$52 -> 4888000 | D46: =SUMPRODUCT(Headcount!D31:D40,Inputs!$D$42:$D$51)*Inputs!$D$52 -> 6448000 | E46: =SUMPRODUCT(Headcount!E31:E40,Inputs!$D$42:$D$51)*Inputs!$D$52 -> 6812000 | F46: =SUMPRODUCT(Headcount!F31:F40,Inputs!$D$42:$D$51)*Inputs!$D$52 -> 7982000 | G46: =SUMPRODUCT(Headcount!G31:G40,Inputs!$D$42:$D$51)*Inputs!$D$52 -> 8632000 | H46: =SUMPRODUCT(Headcount!H31:H40,Inputs!$D$42:$D$51)*Inputs!$D$52 -> 9516000 | I46: =SUMPRODUCT(Headcount!I31:I40,Inputs!$D$42:$D$51)*Inputs!$D$52 -> 9841000 | ... M46: =SUMPRODUCT(Headcount!M31:M40,Inputs!$D$42:$D$51)*Inputs!$D$52 -> 10647000 | N46: =SUM(B46:M46) -> 100061000
A47: Marketing & acquisition | B47: =Inputs!$D$55/12 -> 11666667 | C47: =Inputs!$D$55/12 -> 11666667 | D47: =Inputs!$D$55/12 -> 11666667 | E47: =Inputs!$D$55/12 -> 11666667 | F47: =Inputs!$D$55/12 -> 11666667 | G47: =Inputs!$D$55/12 -> 11666667 | H47: =Inputs!$D$55/12 -> 11666667 | I47: =Inputs!$D$55/12 -> 11666667 | ... M47: =Inputs!$D$55/12 -> 11666667 | N47: =Inputs!$D$55 -> 140000000
A48: Tech infrastructure | B48: =Inputs!$D$63/12 -> 1000000 | C48: =Inputs!$D$63/12 -> 1000000 | D48: =Inputs!$D$63/12 -> 1000000 | E48: =Inputs!$D$63/12 -> 1000000 | F48: =Inputs!$D$63/12 -> 1000000 | G48: =Inputs!$D$63/12 -> 1000000 | H48: =Inputs!$D$63/12 -> 1000000 | I48: =Inputs!$D$63/12 -> 1000000 | ... M48: =Inputs!$D$63/12 -> 1000000 | N48: =Inputs!$D$63 -> 12000000
...

Sheet 3-Year View
A1: 3-YEAR VIEW — Scenarios × Years
B2: Bootstrap | E2: Seed | H2: Aggressive
A3: Метрика | B3: Y1 | C3: Y2 | D3: Y3 | E3: Y1 | F3: Y2 | G3: Y3 | H3: Y1 | I3: Y2 | J3: Y3
A4: Revenue | B4: ='P&L Year 1'!N5 -> 28050000 | C4: =B4*3 -> 84150000 | D4: =B4*6 -> 168300000 | E4: ='P&L Year 1'!N24 -> 129600000 | F4: =E4*3.5 -> 453600000 | G4: =E4*8 -> 1036800000 | H4: ='P&L Year 1'!N43 -> 376580000 | I4: =H4*4 -> 1506320000 | J4: =H4*10 -> 3765800000
A5: Headcount EOY | B5: =Inputs!$B$39 -> 7 | C5: =ROUND(B5*1.7,0) -> 12 | D5: =ROUND(B5*2.5,0) -> 18 | E5: =Inputs!$C$39 -> 15 | F5: =ROUND(E5*2,0) -> 30 | G5: =ROUND(E5*3,0) -> 45 | H5: =Inputs!$D$39 -> 24 | I5: =ROUND(H5*2.2,0) -> 53 | J5: =ROUND(H5*3.5,0) -> 84
A6: Closes (сделки) | B6: ='P&L Year 1'!N21 -> 85 | C6: =B6*3 -> 255 | D6: =B6*6 -> 510 | E6: ='P&L Year 1'!N40 -> 360 | F6: =E6*3.5 -> 1260 | G6: =E6*8 -> 2880 | H6: ='P&L Year 1'!N59 -> 991 | I6: =H6*4 -> 3964 | J6: =H6*10 -> 9910
A7: OpEx (oценочно) | B7: ='P&L Year 1'!N17 -> 40696500 | C7: =B7*1.87 -> 76102455 | D7: =B7*3 -> 122089500 | E7: ='P&L Year 1'!N36 -> 145667000 | F7: =E7*2.2 -> 320467400 | G7: =E7*3.6 -> 524401200 | H7: ='P&L Year 1'!N55 -> 301890000 | I7: =H7*2.42 -> 730573800 | J7: =H7*4.2 -> 1267938000
A8: EBITDA | B8: =B4-B7 -> -12646500 | C8: =C4-C7 -> 8047545 | D8: =D4-D7 -> 46210500 | E8: =E4-E7 -> -16067000 | F8: =F4-F7 -> 133132600 | G8: =G4-G7 -> 512398800 | H8: =H4-H7 -> 74690000 | I8: =I4-I7 -> 775746200 | J8: =J4-J7 -> 2497862000
A9: EBITDA margin (%) | B9: =IFERROR(B8/B4,0) -> -0.45085561 | C9: =IFERROR(C8/C4,0) -> 0.095633333 | D9: =IFERROR(D8/D4,0) -> 0.27457219 | E9: =IFERROR(E8/E4,0) -> -0.12397377 | F9: =IFERROR(F8/F4,0) -> 0.2935022 | G9: =IFERROR(G8/G4,0) -> 0.49421181 | H9: =IFERROR(H8/H4,0) -> 0.19833767 | I9: =IFERROR(I8/I4,0) -> 0.51499429 | J9: =IFERROR(J8/J4,0) -> 0.66330182
A10: Cash position EOY | B10: ='P&L Year 1'!N20 -> 17353500 | C10: =B10+C8 -> 25401045 | D10: =C10+D8 -> 71611545 | E10: ='P&L Year 1'!N39 -> 163933000 | F10: =E10+F8 -> 297065600 | G10: =F10+G8 -> 809464400 | H10: ='P&L Year 1'!N58 -> 424690000 | I10: =H10+I8 -> 1200436200 | J10: =I10+J8 -> 3698298200

Sheet Cap Table
A1: CAP TABLE & USE OF FUNDS
A3: Метрика | B3: Bootstrap | C3: Seed | D3: Aggressive | E3: Комментарий
A4: Cash injection (₽) | B4: =Inputs!B5 -> 30000000 | C4: =Inputs!C5 -> 180000000 | D4: =Inputs!D5 -> 350000000 | E4: Из Inputs
A5: Pre-money valuation (₽) | B5: =Inputs!B7 -> 0 | C5: =Inputs!C7 -> 820000000 | D5: =Inputs!D7 -> 820000000 | E5: Bootstrap = N/A; Seed/Agg ~ $10M
A6: Post-money valuation (₽) | B6: =B4+B5 -> 30000000 | C6: =C4+C5 -> 1000000000 | D6: =D4+D5 -> 1170000000 | E6: Pre + cash
A7: Investor stake (%) | B7: =Inputs!B6 -> 0 | C7: =Inputs!C6 -> 0.18 | D7: =Inputs!D6 -> 0.3 | E7: Дилюция founders
A8: Founders stake post (%) | B8: =1-B7 -> 1 | C8: =1-C7 -> 0.82 | D8: =1-D7 -> 0.7 | E8: 100% - investor stake
A10: USE OF FUNDS — Year 1 (% от cash injection)
A11: Категория | B11: Bootstrap | C11: Seed | D11: Aggressive | E11: Примечание
A12: Payroll | B12: ='P&L Year 1'!N8 -> 19994000 | C12: ='P&L Year 1'!N27 -> 57187000 | D12: ='P&L Year 1'!N46 -> 100061000
A13: Marketing & acquisition | B13: ='P&L Year 1'!N9 -> 12000000 | C13: ='P&L Year 1'!N28 -> 60000000 | D13: ='P&L Year 1'!N47 -> 140000000
A14: Tech infrastructure | B14: ='P&L Year 1'!N10 -> 2400000 | C14: ='P&L Year 1'!N29 -> 6000000 | D14: ='P&L Year 1'!N48 -> 12000000
A15: Office | B15: ='P&L Year 1'!N11 -> 600000 | C15: ='P&L Year 1'!N30 -> 4800000 | D15: ='P&L Year 1'!N49 -> 9600000
A16: Travel | B16: ='P&L Year 1'!N12 -> 1500000 | C16: ='P&L Year 1'!N31 -> 4000000 | D16: ='P&L Year 1'!N50 -> 8000000
A17: Legal / договоры | B17: ='P&L Year 1'!N13 -> 1200000 | C17: ='P&L Year 1'!N32 -> 3000000 | D17: ='P&L Year 1'!N51 -> 5000000
A18: Бухгалтерия | B18: ='P&L Year 1'!N14 -> 600000 | C18: ='P&L Year 1'!N33 -> 1200000 | D18: ='P&L Year 1'!N52 -> 2400000
A19: Прочее / резерв | B19: ='P&L Year 1'!N15 -> 1000000 | C19: ='P&L Year 1'!N34 -> 3000000 | D19: ='P&L Year 1'!N53 -> 6000000
A20: BD commission | B20: ='P&L Year 1'!N16 -> 1402500 | C20: ='P&L Year 1'!N35 -> 6480000 | D20: ='P&L Year 1'!N54 -> 18829000
A21: ВСЕГО OpEx Year 1 | B21: =SUM(B12:B20) -> 40696500 | C21: =SUM(C12:C20) -> 145667000 | D21: =SUM(D12:D20) -> 301890000
A22: Минус: Year 1 Revenue | B22: =-'P&L Year 1'!N5 -> -28050000 | C22: =-'P&L Year 1'!N24 -> -129600000 | D22: =-'P&L Year 1'!N43 -> -376580000
A23: Net cash flow Year 1 (полож. = профицит) | B23: =B21+B22 -> 12646500 | C23: =C21+C22 -> 16067000 | D23: =D21+D22 -> -74690000
A24: Cash remaining EOY | B24: =B4-B23 -> 17353500 | C24: =C4-C23 -> 163933000 | D24: =D4-D23 -> 424690000
A25: Месяцев runway после Y1 | B25: =IF(B23<=0,"профицит",B24/(B23/12)) -> 16.466374 | C25: =IF(C23<=0,"профицит",C24/(C23/12)) -> 122.43704 | D25: =IF(D23<=0,"профицит",D24/(D23/12)) -> профицит
